<?xml version='1.0' ?>

<robot name="arm" xmlns:xacro="http://www.ros.org/wiki/xacro">
	<link name = "base_link">
		<visual>
			<origin rpy = "0 0 0" xyz = "0 0 0" />
			<geometry>
				<box size = "1 1 1" />
			</geometry>
		</visual>
	</link>	

	<joint name = "base_link_link_1" type ="revolute">
		<axis xyz = "0 0 1"/>
		<limit effort="1000.0" lower="-3.14" upper = "3.14" velocity = "0.5"/>
		<origin rpy = "0 0 0" xyz = " 0 0 0.5"/>
		<parent link = "base_link"/>
		<child link = "link_1"/>
	</joint>		

	<link name = "link_1">
		<visual>
			<origin rpy = "0 0 0" xyz = "0 0 0.2" />
			<geometry>
				<cylinder radius = "0.35" length = "0.4" />
			</geometry>
		</visual>
	</link>
</robot>